Failure # 1 (occurred at 2023-04-21_18-59-56)
Traceback (most recent call last):
  File "/home/netease/anaconda3/envs/maca2/lib/python3.8/site-packages/ray/tune/trial_runner.py", line 726, in _process_trial
    result = self.trial_executor.fetch_result(trial)
  File "/home/netease/anaconda3/envs/maca2/lib/python3.8/site-packages/ray/tune/ray_trial_executor.py", line 489, in fetch_result
    result = ray.get(trial_future[0], timeout=DEFAULT_GET_TIMEOUT)
  File "/home/netease/anaconda3/envs/maca2/lib/python3.8/site-packages/ray/worker.py", line 1452, in get
    raise value.as_instanceof_cause()
ray.exceptions.RayTaskError(NameNotFound): [36mray::PPO.train()[39m (pid=187950, ip=10.219.204.81)
  File "python/ray/_raylet.pyx", line 443, in ray._raylet.execute_task
  File "python/ray/_raylet.pyx", line 477, in ray._raylet.execute_task
  File "python/ray/_raylet.pyx", line 481, in ray._raylet.execute_task
  File "python/ray/_raylet.pyx", line 482, in ray._raylet.execute_task
  File "python/ray/_raylet.pyx", line 436, in ray._raylet.execute_task.function_executor
  File "/home/netease/anaconda3/envs/maca2/lib/python3.8/site-packages/ray/rllib/agents/trainer_template.py", line 106, in __init__
    Trainer.__init__(self, config, env, logger_creator)
  File "/home/netease/anaconda3/envs/maca2/lib/python3.8/site-packages/ray/rllib/agents/trainer.py", line 477, in __init__
    super().__init__(config, logger_creator)
  File "/home/netease/anaconda3/envs/maca2/lib/python3.8/site-packages/ray/tune/trainable.py", line 249, in __init__
    self.setup(copy.deepcopy(self.config))
  File "/home/netease/anaconda3/envs/maca2/lib/python3.8/site-packages/ray/rllib/agents/trainer.py", line 630, in setup
    self._init(self.config, self.env_creator)
  File "/home/netease/anaconda3/envs/maca2/lib/python3.8/site-packages/ray/rllib/agents/trainer_template.py", line 133, in _init
    self.workers = self._make_workers(
  File "/home/netease/anaconda3/envs/maca2/lib/python3.8/site-packages/ray/rllib/agents/trainer.py", line 701, in _make_workers
    return WorkerSet(
  File "/home/netease/anaconda3/envs/maca2/lib/python3.8/site-packages/ray/rllib/evaluation/worker_set.py", line 79, in __init__
    remote_spaces = ray.get(self.remote_workers(
ray.exceptions.RayTaskError(NameNotFound): [36mray::RolloutWorker.foreach_policy()[39m (pid=187944, ip=10.219.204.81)
  File "python/ray/_raylet.pyx", line 443, in ray._raylet.execute_task
  File "python/ray/_raylet.pyx", line 477, in ray._raylet.execute_task
  File "python/ray/_raylet.pyx", line 481, in ray._raylet.execute_task
  File "python/ray/_raylet.pyx", line 482, in ray._raylet.execute_task
  File "python/ray/_raylet.pyx", line 436, in ray._raylet.execute_task.function_executor
  File "/home/netease/anaconda3/envs/maca2/lib/python3.8/site-packages/ray/rllib/evaluation/rollout_worker.py", line 366, in __init__
    self.env = _validate_env(env_creator(env_context))
  File "/home/netease/anaconda3/envs/maca2/lib/python3.8/site-packages/ray/rllib/agents/trainer.py", line 571, in <lambda>
    lambda env_context: gym.make(env, **env_context)
  File "/home/netease/anaconda3/envs/maca2/lib/python3.8/site-packages/gym/envs/registration.py", line 569, in make
    _check_version_exists(ns, name, version)
  File "/home/netease/anaconda3/envs/maca2/lib/python3.8/site-packages/gym/envs/registration.py", line 219, in _check_version_exists
    _check_name_exists(ns, name)
  File "/home/netease/anaconda3/envs/maca2/lib/python3.8/site-packages/gym/envs/registration.py", line 197, in _check_name_exists
    raise error.NameNotFound(
gym.error.NameNotFound: Environment cr_env_hier_transfer doesn't exist.

