Failure # 1 (occurred at 2023-04-21_19-00-13)
Traceback (most recent call last):
  File "/home/netease/anaconda3/envs/maca2/lib/python3.8/site-packages/ray/tune/trial_runner.py", line 726, in _process_trial
    result = self.trial_executor.fetch_result(trial)
  File "/home/netease/anaconda3/envs/maca2/lib/python3.8/site-packages/ray/tune/ray_trial_executor.py", line 489, in fetch_result
    result = ray.get(trial_future[0], timeout=DEFAULT_GET_TIMEOUT)
  File "/home/netease/anaconda3/envs/maca2/lib/python3.8/site-packages/ray/worker.py", line 1452, in get
    raise value.as_instanceof_cause()
ray.exceptions.RayTaskError(ImportError): [36mray::PPO.train()[39m (pid=188352, ip=10.219.204.81)
  File "python/ray/_raylet.pyx", line 443, in ray._raylet.execute_task
  File "python/ray/_raylet.pyx", line 477, in ray._raylet.execute_task
  File "python/ray/_raylet.pyx", line 481, in ray._raylet.execute_task
  File "python/ray/_raylet.pyx", line 482, in ray._raylet.execute_task
  File "python/ray/_raylet.pyx", line 436, in ray._raylet.execute_task.function_executor
  File "/home/netease/anaconda3/envs/maca2/lib/python3.8/site-packages/ray/rllib/agents/trainer_template.py", line 106, in __init__
    Trainer.__init__(self, config, env, logger_creator)
  File "/home/netease/anaconda3/envs/maca2/lib/python3.8/site-packages/ray/rllib/agents/trainer.py", line 477, in __init__
    super().__init__(config, logger_creator)
  File "/home/netease/anaconda3/envs/maca2/lib/python3.8/site-packages/ray/tune/trainable.py", line 249, in __init__
    self.setup(copy.deepcopy(self.config))
  File "/home/netease/anaconda3/envs/maca2/lib/python3.8/site-packages/ray/rllib/agents/trainer.py", line 630, in setup
    self._init(self.config, self.env_creator)
  File "/home/netease/anaconda3/envs/maca2/lib/python3.8/site-packages/ray/rllib/agents/trainer_template.py", line 133, in _init
    self.workers = self._make_workers(
  File "/home/netease/anaconda3/envs/maca2/lib/python3.8/site-packages/ray/rllib/agents/trainer.py", line 701, in _make_workers
    return WorkerSet(
  File "/home/netease/anaconda3/envs/maca2/lib/python3.8/site-packages/ray/rllib/evaluation/worker_set.py", line 79, in __init__
    remote_spaces = ray.get(self.remote_workers(
ray.exceptions.RayTaskError(ImportError): [36mray::RolloutWorker.foreach_policy()[39m (pid=188353, ip=10.219.204.81)
  File "python/ray/_raylet.pyx", line 443, in ray._raylet.execute_task
  File "python/ray/_raylet.pyx", line 477, in ray._raylet.execute_task
  File "python/ray/_raylet.pyx", line 481, in ray._raylet.execute_task
  File "python/ray/_raylet.pyx", line 482, in ray._raylet.execute_task
  File "python/ray/_raylet.pyx", line 436, in ray._raylet.execute_task.function_executor
  File "/home/netease/anaconda3/envs/maca2/lib/python3.8/site-packages/ray/rllib/evaluation/rollout_worker.py", line 456, in __init__
    self.policy_map, self.preprocessors = self._build_policy_map(
  File "/home/netease/anaconda3/envs/maca2/lib/python3.8/site-packages/ray/rllib/evaluation/rollout_worker.py", line 1061, in _build_policy_map
    policy_map[name] = cls(obs_space, act_space, merged_conf)
  File "/home/netease/anaconda3/envs/maca2/lib/python3.8/site-packages/ray/rllib/policy/torch_policy_template.py", line 207, in __init__
    self.model = ModelCatalog.get_model_v2(
  File "/home/netease/anaconda3/envs/maca2/lib/python3.8/site-packages/ray/rllib/models/catalog.py", line 413, in get_model_v2
    return wrapper(obs_space, action_space, num_outputs, model_config,
  File "/home/netease/anaconda3/envs/maca2/lib/python3.8/site-packages/ray/rllib/models/torch/fcnet.py", line 22, in __init__
    nn.Module.__init__(self)
  File "/home/netease/anaconda3/envs/maca2/lib/python3.8/site-packages/ray/rllib/utils/framework.py", line 129, in __init__
    raise ImportError("Could not import `torch`.")
ImportError: Could not import `torch`.

